Workbook

Sheet Calculator Dashboard
B2: POWER FACTOR & CAPACITOR BANK DIAGNOSTIC CALCULATOR
B4: Bill Based PF Correction + Existing Capacitor Bank + Solar CT Diagnostic + Transformer Shutdown
B6: BILL DATA | H6: CALCULATED CURRENT PF | K6: ='Engineering Calculations'!B12 -> 0.82910562
B7: Energy - Peak | E7: 368000
B8: Energy - Off Peak | E8: 53243.311 | H8: DESIRED PF | K8: 0.95
B9: Reactive Energy - Peak | E9: 254000
B10: Reactive Energy - Off Peak | E10: 30057.613 | H10: Required Capacitor Capacity | K10: ='Engineering Calculations'!B28 -> 237.5
B11: MDI (kW) | E11: 689.662
B13: Note:This calculation and recommendation are based on the average monthly bill data and the current PF calculated from the information provided. Actual site conditions may differ. For further consultation or a detailed assessment, please contact our PFI Team at power.factor@ke.com.pk
B15: RECOMMENDED CAPACITOR BANK
B16: 100 kVAR | E16: 50 kVAR | H16: 25 kVAR | K16: 12.5 kVAR
B17: ='Engineering Calculations'!B20 -> 2 | E17: ='Engineering Calculations'!B21 -> 0 | H17: ='Engineering Calculations'!B22 -> 1 | K17: ='Engineering Calculations'!B23 -> 1
B18: 7.5 kVAR | E18: 5 kVAR | H18: 2.5 kVAR | K18: 3.5 kVAR
B19: ='Engineering Calculations'!B24 -> 0 | E19: ='Engineering Calculations'!B25 -> 0 | H19: ='Engineering Calculations'!B26 -> 0 | K19: ='Engineering Calculations'!B27 -> 1
B21: TOTAL RECOMMENDED BANK | H21: STEP CONFIGURATION
B22: ='Engineering Calculations'!B28 -> 237.5 | H22: ='Engineering Calculations'!B29 -> 2 × 100 kVAR, 1 × 25 kVAR, 1 × 12.5 kVAR, 1 × 2.5 kVAR
B25: EXISTING CAPACITOR BANK
B26: Do you already have a capacitor bank? | H26: Yes
B27: 100 kVAR | E27: 50 kVAR | H27: 25 kVAR | K27: 12.5 kVAR
B28: 2 | E28: 1 | H28: 1 | K28: 1
B29: 7.5 kVAR | E29: 5 kVAR | H29: 3.5 kVAR | K29: 2.5 kVAR
B30: 2 | E30: 1 | H30: 1 | K30: 1
B31: INSTALLED CAPACITY | H31: BANK VS REQUIRED
B32: ='Engineering Calculations'!B41 -> 313.5 | H32: ='Engineering Calculations'!B42 -> Installed bank is theoretically sufficient
B36: TRANSFORMER ENERGIZED / FACTORY SHUTDOWN
B37: Factory Load (kW) | E37: Transformer Rating (kVA) | H37: Existing Capacitor Bank? | K37: Yes / No
B38: 0 | E38: 750 | H38: Est. No-load kVAR | K38: ='Engineering Calculations'!B56 -> 9.2878953
B41: RECOMMENDED NO-LOAD COMPENSATION
B42: ='Engineering Calculations'!B57 -> 12.5
B44: Engineering estimates are indicative. Final capacitor-bank selection, CT location, and transformer no load compensation should be verified against actual site measurements, equipment data and the applicable tariff/metering arrangement.

Sheet Engineering Calculations
A1: ENGINEERING CALCULATIONS
A3: Bill Inputs
A5: Energy - Peak | B5: ='Calculator Dashboard'!E7 -> 368000
A6: Energy - Off Peak | B6: ='Calculator Dashboard'!E8 -> 53243.311
A7: Reactive Energy - Peak | B7: ='Calculator Dashboard'!E9 -> 254000
A8: Reactive Energy - Off Peak | B8: ='Calculator Dashboard'!E10 -> 30057.613
A9: MDI (kW) | B9: ='Calculator Dashboard'!E11 -> 689.662
A10: Desired PF | B10: ='Calculator Dashboard'!K8 -> 0.95
A12: Calculated Current PF | B12: =IFERROR((B5+B6)/SQRT((B5+B6)^2+(B7+B8)^2),0) -> 0.82910562
A13: Total Active Energy (kWh) | B13: =B5+B6 -> 421243.31
A14: Total Reactive Energy (kVARh) | B14: =B7+B8 -> 284057.61
A15: Target Reactive Energy (kVARh) — internal calculation | B15: =B13*TAN(ACOS(B10)) -> 138455.98
A16: Required Reactive Energy Compensation (kVARh) — internal calculation | B16: =MAX(0,B14-B15) -> 145601.63
A17: Calculated Capacitor Requirement (kVAR) using MDI | B17: =MAX(0,B9*(TAN(ACOS(B12))-TAN(ACOS(B10)))) -> 238.37984
A20: 100 kVAR Steps | B20: =INT(B17/100) -> 2 | D20: Required | E20: Recommended
A21: 50 kVAR Steps | B21: =INT(MAX(0,B17-B20*100)/50) -> 0 | D21: kVAR | E21: kVAR
A22: 25 kVAR Steps | B22: =INT(MAX(0,B17-B20*100-B21*50)/25) -> 1 | D22: =B17 -> 238.37984 | E22: =B28 -> 237.5
A23: 12.5 kVAR Steps | B23: =INT(MAX(0,B17-B20*100-B21*50-B22*25)/12.5) -> 1
A24: 7.5 kVAR Steps | B24: =INT(MAX(0,B17-B20*100-B21*50-B22*25-B23*12.5)/7.5) -> 0
A25: 5 kVAR Steps | B25: =INT(MAX(0,B17-B20*100-B21*50-B22*25-B23*12.5-B24*7.5)/5) -> 0
A26: 3.5 kVAR Steps | B26: =INT(MAX(0,B17-B20*100-B21*50-B22*25-B23*12.5-B24*7.5-B25*5)/3.5) -> 0
A27: 2.5 kVAR Steps | B27: =IF(MAX(0,B17-B20*100-B21*50-B22*25-B23*12.5-B24*7.5-B25*5-B26*3.5)>0,1,0) -> 1
A28: Required Capacitor Capacity (kVAR) | B28: =B20*100+B21*50+B22*25+B23*12.5 -> 237.5
A29: Step Configuration | B29: =IF(B20>0,B20&" × 100 kVAR, ","")&IF(B21>0,B21&" × 50 kVAR, ","")&IF(B22>0,B22&" × 25 kVAR, ","")&IF(B23>0,B23&" × 12.5 kVAR, ","")&IF(B24>0,B24&" × 7.5 kVAR, ","")&IF(B25>0,B25&" × 5 kVAR, ","")&IF(B26>0,B26&" × 3.5 kVAR, ","")&IF(B27>0,B27&" × 2.5 kVAR","") -> 2 × 100 kVAR, 1 × 25 kVAR, 1 × 12.5 kVAR, 1 × 2.5 kVAR
A33: Existing 100 kVAR qty | B33: ='Calculator Dashboard'!B28 -> 2
A34: Existing 50 kVAR qty | B34: ='Calculator Dashboard'!E28 -> 1
A35: Existing 25 kVAR qty | B35: ='Calculator Dashboard'!H28 -> 1
A36: Existing 12.5 kVAR qty | B36: ='Calculator Dashboard'!K28 -> 1
A37: Existing 7.5 kVAR qty | B37: ='Calculator Dashboard'!B30 -> 2
A38: Existing 5 kVAR qty | B38: ='Calculator Dashboard'!E30 -> 1
A39: Existing 3.5 kVAR qty | B39: ='Calculator Dashboard'!H30 -> 1
A40: Existing 2.5 kVAR qty | B40: ='Calculator Dashboard'!K30 -> 1
A41: Installed Capacity (kVAR) | B41: =B33*100+B34*50+B35*25+B36*12.5+B37*7.5+B38*5+B39*3.5+B40*2.5 -> 313.5
A42: Bank Adequacy | B42: =IF(B41>=B17,"Installed bank is theoretically sufficient","Installed bank is below estimated requirement") -> Installed bank is theoretically sufficient
A44: Solar PV | B44: ='Calculator Dashboard'!#REF! -> #REF!
A45: CT Location | B45: ='Calculator Dashboard'!#REF! -> #REF!
A47: Solar / CT Diagnostic | B47: =IF(B44="No","Solar diagnostic not applicable",IF(B45="Upstream of Solar","CT location is generally aligned with utility-side PF measurement; verify CT polarity/phase and controller configuration",IF(B45="Downstream of Solar","Check CT measurement philosophy: controller may not see net utility-side power correctly; verify against PCC and manufacturer guidance","Select a CT location"))) -> #REF!
A52: Factory Load | B52: ='Calculator Dashboard'!B38 -> 0
A53: Transformer Rating | B53: ='Calculator Dashboard'!E38 -> 750
A54: Estimated Transformer No-load kVA | B54: =B53*IF(B53<=315,0.0175,IF(B53<=630,0.015,IF(B53<=1000,0.0125,0.01))) -> 9.375
...

Sheet Assumptions & Notes
A1: ASSUMPTIONS & NOTES
A3: PFC formula | B3: Qc = P × [tan(cos⁻¹(PFexisting)) − tan(cos⁻¹(PFdesired))].
A4: Bill PF | B4: Billing-period PF is derived from total active and reactive energy: PF = kWh / √(kWh² + kVARh²).
A5: Bill terminology | B5: Customer inputs use the bill wording: Energy - Peak, Energy - Off Peak, Reactive Energy - Peak, Reactive Energy - Off Peak, MDI (kW).
A6: Capacitor sizing | B6: MDI and calculated billing PF are used to estimate a practical capacitor-bank kVAR requirement.
A7: Existing bank | B7: Installed step quantities are compared with the estimated requirement; adequacy does not prove that every capacitor step is healthy.
A8: Solar CT diagnostic | B8: CT location must be evaluated against the actual single-line diagram, PCC and controller measurement philosophy. The calculator flags cases for verification; it does not certify an installation.
A9: Transformer no-load | B9: Typical rating-band assumptions are used because nameplate/test-certificate no-load data are often unavailable.
A10: Engineering caution | B10: Final design should be verified with site measurements, manufacturer data, protection/metering configuration and applicable tariff requirements.
